[32mINFO    [0m root:task_utility.py:14 Executing create task api
[32mINFO    [0m root:task_utility.py:15 Sending the POST request http://localhost:5000/tasks
[35mDEBUG   [0m urllib3.connectionpool:connectionpool.py:226 Starting new HTTP connection (1): localhost:5000
[35mDEBUG   [0m urllib3.connectionpool:connectionpool.py:433 http://localhost:5000 "POST /tasks HTTP/1.1" 200 23
[32mINFO    [0m root:task_utility.py:18 Got the status  code as 200
[32mINFO    [0m root:task_utility.py:24 {'task_id': 'lKai4Spr'}
[32mINFO    [0m root:task_utility.py:25 Created Task_id is :: lKai4Spr
[32mINFO    [0m root:test_task_update.py:37 Executing GET Task API using deleted task id
[32mINFO    [0m root:test_task_update.py:38 Sending the GET request with task id lKai4Spr
[35mDEBUG   [0m urllib3.connectionpool:connectionpool.py:226 Starting new HTTP connection (1): localhost:5000
[35mDEBUG   [0m urllib3.connectionpool:connectionpool.py:433 http://localhost:5000 "DELETE /tasks/lKai4Spr HTTP/1.1" 200 23
[31m[1mERROR   [0m root:task_utility.py:102 Getting assertion error while executing updated task api Delete task api didn't work