[32mINFO    [0m root:task_utility.py:14 Executing create task api
[32mINFO    [0m root:task_utility.py:15 Sending the POST request http://localhost:5000/tasks
[35mDEBUG   [0m urllib3.connectionpool:connectionpool.py:226 Starting new HTTP connection (1): localhost:5000
[35mDEBUG   [0m urllib3.connectionpool:connectionpool.py:433 http://localhost:5000 "POST /tasks HTTP/1.1" 200 23
[32mINFO    [0m root:task_utility.py:18 Got the status  code as 200
[32mINFO    [0m root:task_utility.py:24 {'task_id': 'VqwCcPGJ'}
[32mINFO    [0m root:task_utility.py:25 Created Task_id is :: VqwCcPGJ
[32mINFO    [0m root:test_task_update.py:29 Executing GET Task API using deleted task id
[32mINFO    [0m root:test_task_update.py:30 Sending the GET request with task id 123
[35mDEBUG   [0m urllib3.connectionpool:connectionpool.py:226 Starting new HTTP connection (1): localhost:5000
[35mDEBUG   [0m urllib3.connectionpool:connectionpool.py:433 http://localhost:5000 "GET /tasks/123 HTTP/1.1" 404 2
[31m[1mERROR   [0m root:task_utility.py:34 Get task api didn't work as we got the error Unable to get the Task details from the task id 123