[32mINFO    [0m root:task_utility.py:14 Executing create task api
[32mINFO    [0m root:task_utility.py:15 Sending the POST request http://localhost:5000/tasks
[35mDEBUG   [0m urllib3.connectionpool:connectionpool.py:226 Starting new HTTP connection (1): localhost:5000
[35mDEBUG   [0m urllib3.connectionpool:connectionpool.py:433 http://localhost:5000 "POST /tasks HTTP/1.1" 200 23
[32mINFO    [0m root:task_utility.py:18 Got the status  code as 200
[32mINFO    [0m root:task_utility.py:24 {'task_id': 'ERkSuN6C'}
[32mINFO    [0m root:task_utility.py:25 Created Task_id is :: ERkSuN6C
[32mINFO    [0m root:test_task_update.py:36 Executing Modify Task API
[32mINFO    [0m root:test_task_update.py:37 Sending the POST request with task id 456
[35mDEBUG   [0m urllib3.connectionpool:connectionpool.py:226 Starting new HTTP connection (1): localhost:5000
[35mDEBUG   [0m urllib3.connectionpool:connectionpool.py:433 http://localhost:5000 "PUT /tasks/456 HTTP/1.1" 404 2
[31m[1mERROR   [0m root:task_utility.py:74 Getting assertion error while executing updated task api Unable to updated the task